Workbook

Sheet Dashboard
A1: NUTRITIONAL PROGRAMME — PERSONALISED MEAL PLANNING SYSTEM
A2: Evidence-based approach | Structured tracking | Sustainable fat loss protocol
A4: CLIENT PROFILE & BASELINE METRICS | F4: WEEKLY COMPLIANCE SUMMARY
A5: Metric | B5: Value | C5: Metric | D5: Value | F5: Week | G5: Avg. Kcal | H5: Avg. Protein | I5: Within Target? | J5: Weight (kg) | K5: Trend
A6: Starting Weight (kg) | B6: 62 | C6: Goal Weight (kg) | D6: 55 | F6: Week 1 | G6: =IFERROR(ROUND(AVERAGEIF(WeekKcal,">0"),0),"") | H6: =IFERROR(ROUND(AVERAGEIF(WeekPro,">0"),0),"") | I6: =IF(N(G6)=0,"—",IF(G6<TgtKcal-400,"▼ Kurang",IF(G6<=TgtKcal,"✓ Ya","▲ Lebih"))) -> — | J6: =IF(INDEX(BodyWt,1)="","",INDEX(BodyWt,1)) | K6: ="—" -> —
A7: Height (cm) | C7: Age | F7: Week 2 | G7: [AUTO] | H7: [AUTO] | I7: =IF(N(G7)=0,"—",IF(G7<TgtKcal-400,"▼ Kurang",IF(G7<=TgtKcal,"✓ Ya","▲ Lebih"))) -> — | J7: =IF(INDEX(BodyWt,2)="","",INDEX(BodyWt,2)) | K7: =IF(OR(INDEX(BodyWt,2)="",INDEX(BodyWt,1)=""),"—",IF(INDEX(BodyWt,2)<INDEX(BodyWt,1),"▼ turun",IF(INDEX(BodyWt,2)>INDEX(BodyWt,1),"▲ naik","= sama"))) -> —
A8: Estimated BMR (kcal) | B8: =IFERROR(ROUND(10*B6+6.25*B7-5*D7-161,0),"isi height + age") -> 459 | C8: TDEE — Sedentary (kcal) | D8: =IFERROR(ROUND(B8*1.2,0),"") -> 551 | F8: Week 3 | G8: [AUTO] | H8: [AUTO] | I8: =IF(N(G8)=0,"—",IF(G8<TgtKcal-400,"▼ Kurang",IF(G8<=TgtKcal,"✓ Ya","▲ Lebih"))) -> — | J8: =IF(INDEX(BodyWt,3)="","",INDEX(BodyWt,3)) | K8: =IF(OR(INDEX(BodyWt,3)="",INDEX(BodyWt,2)=""),"—",IF(INDEX(BodyWt,3)<INDEX(BodyWt,2),"▼ turun",IF(INDEX(BodyWt,3)>INDEX(BodyWt,2),"▲ naik","= sama"))) -> —
A9: TDEE — Moderate (kcal) | B9: =IFERROR(ROUND(B8*1.55,0),"") -> 711 | C9: TDEE — Active (kcal) | D9: =IFERROR(ROUND(B8*1.725,0),"") -> 792 | F9: Week 4 | G9: [AUTO] | H9: [AUTO] | I9: =IF(N(G9)=0,"—",IF(G9<TgtKcal-400,"▼ Kurang",IF(G9<=TgtKcal,"✓ Ya","▲ Lebih"))) -> — | J9: =IF(INDEX(BodyWt,4)="","",INDEX(BodyWt,4)) | K9: =IF(OR(INDEX(BodyWt,4)="",INDEX(BodyWt,3)=""),"—",IF(INDEX(BodyWt,4)<INDEX(BodyWt,3),"▼ turun",IF(INDEX(BodyWt,4)>INDEX(BodyWt,3),"▲ naik","= sama"))) -> —
A10: Body Fat % (est.) | C10: Lean Body Mass (kg) | D10: =IFERROR(ROUND(B6*(1-B10/100),1),"") -> 62 | F10: Week 5 | G10: [AUTO] | H10: [AUTO] | I10: =IF(N(G10)=0,"—",IF(G10<TgtKcal-400,"▼ Kurang",IF(G10<=TgtKcal,"✓ Ya","▲ Lebih"))) -> — | J10: =IF(INDEX(BodyWt,5)="","",INDEX(BodyWt,5)) | K10: =IF(OR(INDEX(BodyWt,5)="",INDEX(BodyWt,4)=""),"—",IF(INDEX(BodyWt,5)<INDEX(BodyWt,4),"▼ turun",IF(INDEX(BodyWt,5)>INDEX(BodyWt,4),"▲ naik","= sama"))) -> —
A11: Programme Start Date | C11: Target Date (12 weeks) | D11: =IFERROR(B11+84,"") -> 84 | F11: Week 6 | G11: [AUTO] | H11: [AUTO] | I11: =IF(N(G11)=0,"—",IF(G11<TgtKcal-400,"▼ Kurang",IF(G11<=TgtKcal,"✓ Ya","▲ Lebih"))) -> — | J11: =IF(INDEX(BodyWt,6)="","",INDEX(BodyWt,6)) | K11: =IF(OR(INDEX(BodyWt,6)="",INDEX(BodyWt,5)=""),"—",IF(INDEX(BodyWt,6)<INDEX(BodyWt,5),"▼ turun",IF(INDEX(BodyWt,6)>INDEX(BodyWt,5),"▲ naik","= sama"))) -> —
F12: Week 7 | G12: [AUTO] | H12: [AUTO] | I12: =IF(N(G12)=0,"—",IF(G12<TgtKcal-400,"▼ Kurang",IF(G12<=TgtKcal,"✓ Ya","▲ Lebih"))) -> — | J12: =IF(INDEX(BodyWt,7)="","",INDEX(BodyWt,7)) | K12: =IF(OR(INDEX(BodyWt,7)="",INDEX(BodyWt,6)=""),"—",IF(INDEX(BodyWt,7)<INDEX(BodyWt,6),"▼ turun",IF(INDEX(BodyWt,7)>INDEX(BodyWt,6),"▲ naik","= sama"))) -> —
A13: DAILY NUTRITIONAL TARGETS | F13: Week 8 | G13: [AUTO] | H13: [AUTO] | I13: =IF(N(G13)=0,"—",IF(G13<TgtKcal-400,"▼ Kurang",IF(G13<=TgtKcal,"✓ Ya","▲ Lebih"))) -> — | J13: =IF(INDEX(BodyWt,8)="","",INDEX(BodyWt,8)) | K13: =IF(OR(INDEX(BodyWt,8)="",INDEX(BodyWt,7)=""),"—",IF(INDEX(BodyWt,8)<INDEX(BodyWt,7),"▼ turun",IF(INDEX(BodyWt,8)>INDEX(BodyWt,7),"▲ naik","= sama"))) -> —
A14: Macronutrient | B14: Target | C14: Range (±10%) | D14: Notes | F14: Week 9 | G14: [AUTO] | H14: [AUTO] | I14: =IF(N(G14)=0,"—",IF(G14<TgtKcal-400,"▼ Kurang",IF(G14<=TgtKcal,"✓ Ya","▲ Lebih"))) -> — | J14: =IF(INDEX(BodyWt,9)="","",INDEX(BodyWt,9)) | K14: =IF(OR(INDEX(BodyWt,9)="",INDEX(BodyWt,8)=""),"—",IF(INDEX(BodyWt,9)<INDEX(BodyWt,8),"▼ turun",IF(INDEX(BodyWt,9)>INDEX(BodyWt,8),"▲ naik","= sama"))) -> —
A15: Total Energy (kcal) | B15: 1500 | C15: 1350–1650 | D15: Moderate deficit: ~500 kcal below TDEE | F15: Week 10 | G15: [AUTO] | H15: [AUTO] | I15: =IF(N(G15)=0,"—",IF(G15<TgtKcal-400,"▼ Kurang",IF(G15<=TgtKcal,"✓ Ya","▲ Lebih"))) -> — | J15: =IF(INDEX(BodyWt,10)="","",INDEX(BodyWt,10)) | K15: =IF(OR(INDEX(BodyWt,10)="",INDEX(BodyWt,9)=""),"—",IF(INDEX(BodyWt,10)<INDEX(BodyWt,9),"▼ turun",IF(INDEX(BodyWt,10)>INDEX(BodyWt,9),"▲ naik","= sama"))) -> —
A16: Protein (g) | B16: 90 | C16: 81–99 | D16: 1.4–1.6 g/kg target body weight; preserves LBM in deficit | F16: Week 11 | G16: [AUTO] | H16: [AUTO] | I16: =IF(N(G16)=0,"—",IF(G16<TgtKcal-400,"▼ Kurang",IF(G16<=TgtKcal,"✓ Ya","▲ Lebih"))) -> — | J16: =IF(INDEX(BodyWt,11)="","",INDEX(BodyWt,11)) | K16: =IF(OR(INDEX(BodyWt,11)="",INDEX(BodyWt,10)=""),"—",IF(INDEX(BodyWt,11)<INDEX(BodyWt,10),"▼ turun",IF(INDEX(BodyWt,11)>INDEX(BodyWt,10),"▲ naik","= sama"))) -> —
A17: Carbohydrates (g) | B17: 130 | C17: 117–143 | D17: Sufficient for cognitive function & training performance | F17: Week 12 | G17: [AUTO] | H17: [AUTO] | I17: =IF(N(G17)=0,"—",IF(G17<TgtKcal-400,"▼ Kurang",IF(G17<=TgtKcal,"✓ Ya","▲ Lebih"))) -> — | J17: =IF(INDEX(BodyWt,12)="","",INDEX(BodyWt,12)) | K17: =IF(OR(INDEX(BodyWt,12)="",INDEX(BodyWt,11)=""),"—",IF(INDEX(BodyWt,12)<INDEX(BodyWt,11),"▼ turun",IF(INDEX(BodyWt,12)>INDEX(BodyWt,11),"▲ naik","= sama"))) -> —
A18: Dietary Fat (g) | B18: 50 | C18: 45–55 | D18: Minimum 0.8 g/kg; hormone production & nutrient absorption | F18: Week 1 auto dari Weekly Meal Schedule. Minggu 2 ke atas — salin purata ke sini bila mula minggu baru.
A19: Dietary Fibre (g) | B19: 30 | C19: 25–35 | D19: Promotes satiety & gut microbiome diversity
A20: Water Intake (ml) | B20: 2500 | C20: 2000–3000 | D20: Baseline; increase with activity & ambient temperature
A21: Omega-3 EPA+DHA (mg) | B21: 1000 | C21: 500–2000 | D21: Salmon provides ~1.5g per 150g serving
A23: PROGRAMME PRINCIPLES & METHODOLOGY
A24: 1. ENERGY DEFICIT: A sustained caloric deficit of 300–500 kcal/day produces fat loss of 0.4–0.6 kg/week while minimising lean tissue catabolism.
A25: 2. PROTEIN PRIORITISATION: Protein intake ≥1.4 g/kg target weight preserves muscle mass, increases diet-induced thermogenesis, and enhances satiety signalling.
A26: 3. MICRONUTRIENT DENSITY: Minimum 5 servings/day of vegetables and 2 servings/day of fruit to ensure adequate fibre, vitamins, and phytonutrients.
A27: 4. MEAL FREQUENCY: 3 main meals + 1–2 snacks distributed across 10–12 hours supports stable blood glucose and reduces unplanned eating.
A28: 5. HYDRATION PROTOCOL: 250–500ml water upon waking; 250ml before each meal; additional intake during and after physical activity.
A29: 6. ADHERENCE MECHANISM: One flexible meal (≤800 kcal) per week to support psychological sustainability and social participation without compromising weekly deficit.
A30: 7. PROGRESS MONITORING: Weigh-in once weekly (morning, post-void, pre-breakfast, consistent clothing); track 7-day rolling average rather than daily fluctuations.
A31: 8. SLEEP & RECOVERY: 7–9 hours sleep; sleep restriction impairs ghrelin/leptin regulation and increases hedonic food cravings by 24–45%.

Sheet Streak & Badges
A1: STREAK & BADGES
A2: Semua auto dari Weekly Meal Schedule & Body Composition. Tak perlu isi apa-apa di sini.
A4: MINGGU INI · THIS WEEK
A5: Hari / Day | B5: Kcal | C5: Protein (g) | D5: Salmon | E5: Target | F5: Streak | G5: Status
A6: Isnin / Monday | B6: =N('Weekly Meal Schedule'!E12) -> 0 | C6: =N('Weekly Meal Schedule'!F12) -> 0 | D6: =COUNTIF('Weekly Meal Schedule'!C6:C11,"*Salmon*") -> 0 | E6: =TgtKcal -> 1500 | F6: =IF(B6>0,1,0) -> 0 | G6: =IF(B6=0,"—",IF(B6<TgtKcal-400,"▼ Kurang sangat",IF(B6<=TgtKcal,"✓ Ikut target",IF(B6<=TgtKcal+250,"~ Dekat","▲ Lebih")))) -> —
A7: Selasa / Tuesday | B7: =N('Weekly Meal Schedule'!E24) -> 0 | C7: =N('Weekly Meal Schedule'!F24) -> 0 | D7: =COUNTIF('Weekly Meal Schedule'!C18:C23,"*Salmon*") -> 0 | E7: =TgtKcal -> 1500 | F7: =IF(B7>0,F6+1,0) -> 0 | G7: =IF(B7=0,"—",IF(B7<TgtKcal-400,"▼ Kurang sangat",IF(B7<=TgtKcal,"✓ Ikut target",IF(B7<=TgtKcal+250,"~ Dekat","▲ Lebih")))) -> —
A8: Rabu / Wednesday | B8: =N('Weekly Meal Schedule'!E36) -> 0 | C8: =N('Weekly Meal Schedule'!F36) -> 0 | D8: =COUNTIF('Weekly Meal Schedule'!C30:C35,"*Salmon*") -> 0 | E8: =TgtKcal -> 1500 | F8: =IF(B8>0,F7+1,0) -> 0 | G8: =IF(B8=0,"—",IF(B8<TgtKcal-400,"▼ Kurang sangat",IF(B8<=TgtKcal,"✓ Ikut target",IF(B8<=TgtKcal+250,"~ Dekat","▲ Lebih")))) -> —
A9: Khamis / Thursday | B9: =N('Weekly Meal Schedule'!E48) -> 0 | C9: =N('Weekly Meal Schedule'!F48) -> 0 | D9: =COUNTIF('Weekly Meal Schedule'!C42:C47,"*Salmon*") -> 0 | E9: =TgtKcal -> 1500 | F9: =IF(B9>0,F8+1,0) -> 0 | G9: =IF(B9=0,"—",IF(B9<TgtKcal-400,"▼ Kurang sangat",IF(B9<=TgtKcal,"✓ Ikut target",IF(B9<=TgtKcal+250,"~ Dekat","▲ Lebih")))) -> —
A10: Jumaat / Friday | B10: =N('Weekly Meal Schedule'!E60) -> 0 | C10: =N('Weekly Meal Schedule'!F60) -> 0 | D10: =COUNTIF('Weekly Meal Schedule'!C54:C59,"*Salmon*") -> 0 | E10: =TgtKcal -> 1500 | F10: =IF(B10>0,F9+1,0) -> 0 | G10: =IF(B10=0,"—",IF(B10<TgtKcal-400,"▼ Kurang sangat",IF(B10<=TgtKcal,"✓ Ikut target",IF(B10<=TgtKcal+250,"~ Dekat","▲ Lebih")))) -> —
A11: Sabtu / Saturday | B11: =N('Weekly Meal Schedule'!E72) -> 0 | C11: =N('Weekly Meal Schedule'!F72) -> 0 | D11: =COUNTIF('Weekly Meal Schedule'!C66:C71,"*Salmon*") -> 0 | E11: =TgtKcal -> 1500 | F11: =IF(B11>0,F10+1,0) -> 0 | G11: =IF(B11=0,"—",IF(B11<TgtKcal-400,"▼ Kurang sangat",IF(B11<=TgtKcal,"✓ Ikut target",IF(B11<=TgtKcal+250,"~ Dekat","▲ Lebih")))) -> —
A12: Ahad / Sunday | B12: =N('Weekly Meal Schedule'!E84) -> 0 | C12: =N('Weekly Meal Schedule'!F84) -> 0 | D12: =COUNTIF('Weekly Meal Schedule'!C78:C83,"*Salmon*") -> 0 | E12: =TgtKcal -> 1500 | F12: =IF(B12>0,F11+1,0) -> 0 | G12: =IF(B12=0,"—",IF(B12<TgtKcal-400,"▼ Kurang sangat",IF(B12<=TgtKcal,"✓ Ikut target",IF(B12<=TgtKcal+250,"~ Dekat","▲ Lebih")))) -> —
A14: RINGKASAN · SUMMARY
A15: Hari log Days logged | B15: Ikut target On target | C15: Salmon Meals | D15: Streak terbaik Best run | E15: Protein ok Days ≥ target | F15: Berat terkini Latest (kg) | G15: Lagi berapa To goal (kg)
A16: =COUNTIF(B6:B12,">0")&" / 7" -> 0 / 7 | B16: =COUNTIFS(B6:B12,">="&TgtKcal-400,B6:B12,"<="&TgtKcal)&" / 7" -> 0 / 7 | C16: =SUM(D6:D12) -> 0 | D16: =MAX(F6:F12) -> 0 | E16: =COUNTIF(C6:C12,">="&TgtPro)&" / 7" -> 0 / 7 | F16: =IFERROR(LOOKUP(9.99999999999999E+307,BodyWt),"—") -> — | G16: =IFERROR(ROUND(LOOKUP(9.99999999999999E+307,BodyWt)-GoalWt,1),"—") -> —
A18: LENCANA · BADGES
A19: Lencana / Badge | B19: Syarat / How to unlock | F19: Status
A20: Langkah Pertama | B20: Log mana-mana satu hari | F20: =IF(COUNTIF(B6:B12,">0")>=1,"UNLOCKED","—") -> —
A21: Tiga Hari Lurus | B21: Streak 3 hari berturut-turut | F21: =IF(MAX(F6:F12)>=3,"UNLOCKED","—") -> —
A22: Seminggu Penuh | B22: Log semua 7 hari | F22: =IF(COUNTIF(B6:B12,">0")=7,"UNLOCKED","—") -> —
A23: Omega Squad | B23: 3 hidangan salmon dalam seminggu | F23: =IF(SUM(D6:D12)>=3,"UNLOCKED","—") -> —
A24: Protein Power | B24: 4 hari capai target protein | F24: =IF(COUNTIF(C6:C12,">="&TgtPro)>=4,"UNLOCKED","—") -> —
A25: Disiplin | B25: 5 hari ikut target kalori | F25: =IF(COUNTIFS(B6:B12,">="&TgtKcal-400,B6:B12,"<="&TgtKcal)>=5,"UNLOCKED","—") -> —
A26: Turun 1 kg | B26: Berat turun 1 kg dari mula | F26: =IF(IFERROR(StartWt-LOOKUP(9.99999999999999E+307,BodyWt),0)>=1,"UNLOCKED","—") -> —
A27: Turun 3 kg | B27: Berat turun 3 kg dari mula | F27: =IF(IFERROR(StartWt-LOOKUP(9.99999999999999E+307,BodyWt),0)>=3,"UNLOCKED","—") -> —
A28: Sampai Goal | B28: Capai berat sasaran | F28: =IF(IFERROR(LOOKUP(9.99999999999999E+307,BodyWt),99999)<=GoalWt,"UNLOCKED","—") -> —

Sheet Weekly Meal Schedule
A1: WEEKLY MEAL SCHEDULE — 7-DAY DIETARY RECORD
A2: Record all food and beverages consumed. Use the Food Database sheet for macro values. Weigh raw portions where possible for accuracy.
A3: Kuning = isi sendiri · Kelabu = auto · Pilih makanan dari dropdown, makro isi sendiri
A4: MONDAY · ISNIN
A5: Meal | B5: Time | C5: Food Item | D5: Servings (×) | E5: Kcal | F5: Protein (g) | G5: Carbs (g) | H5: Fat (g) | I5: Fibre (g) | J5: Notes
A6: Breakfast / Sarapan | E6: =IFERROR(INDEX(FoodKcal,MATCH(C6,FoodName,0))*D6,"") | F6: =IFERROR(INDEX(FoodPro,MATCH(C6,FoodName,0))*D6,"") | G6: =IFERROR(INDEX(FoodCarb,MATCH(C6,FoodName,0))*D6,"") | H6: =IFERROR(INDEX(FoodFat,MATCH(C6,FoodName,0))*D6,"") | I6: =IFERROR(INDEX(FoodFib,MATCH(C6,FoodName,0))*D6,"")
A7: Mid-Morning Snack / Snek Pagi | E7: =IFERROR(INDEX(FoodKcal,MATCH(C7,FoodName,0))*D7,"") | F7: =IFERROR(INDEX(FoodPro,MATCH(C7,FoodName,0))*D7,"") | G7: =IFERROR(INDEX(FoodCarb,MATCH(C7,FoodName,0))*D7,"") | H7: =IFERROR(INDEX(FoodFat,MATCH(C7,FoodName,0))*D7,"") | I7: =IFERROR(INDEX(FoodFib,MATCH(C7,FoodName,0))*D7,"")
A8: Lunch / Tengahari | E8: =IFERROR(INDEX(FoodKcal,MATCH(C8,FoodName,0))*D8,"") | F8: =IFERROR(INDEX(FoodPro,MATCH(C8,FoodName,0))*D8,"") | G8: =IFERROR(INDEX(FoodCarb,MATCH(C8,FoodName,0))*D8,"") | H8: =IFERROR(INDEX(FoodFat,MATCH(C8,FoodName,0))*D8,"") | I8: =IFERROR(INDEX(FoodFib,MATCH(C8,FoodName,0))*D8,"")
A9: Afternoon Snack / Snek Petang | E9: =IFERROR(INDEX(FoodKcal,MATCH(C9,FoodName,0))*D9,"") | F9: =IFERROR(INDEX(FoodPro,MATCH(C9,FoodName,0))*D9,"") | G9: =IFERROR(INDEX(FoodCarb,MATCH(C9,FoodName,0))*D9,"") | H9: =IFERROR(INDEX(FoodFat,MATCH(C9,FoodName,0))*D9,"") | I9: =IFERROR(INDEX(FoodFib,MATCH(C9,FoodName,0))*D9,"")
A10: Dinner / Malam | E10: =IFERROR(INDEX(FoodKcal,MATCH(C10,FoodName,0))*D10,"") | F10: =IFERROR(INDEX(FoodPro,MATCH(C10,FoodName,0))*D10,"") | G10: =IFERROR(INDEX(FoodCarb,MATCH(C10,FoodName,0))*D10,"") | H10: =IFERROR(INDEX(FoodFat,MATCH(C10,FoodName,0))*D10,"") | I10: =IFERROR(INDEX(FoodFib,MATCH(C10,FoodName,0))*D10,"")
A11: Evening (optional) / Malam (pilihan) | E11: =IFERROR(INDEX(FoodKcal,MATCH(C11,FoodName,0))*D11,"") | F11: =IFERROR(INDEX(FoodPro,MATCH(C11,FoodName,0))*D11,"") | G11: =IFERROR(INDEX(FoodCarb,MATCH(C11,FoodName,0))*D11,"") | H11: =IFERROR(INDEX(FoodFat,MATCH(C11,FoodName,0))*D11,"") | I11: =IFERROR(INDEX(FoodFib,MATCH(C11,FoodName,0))*D11,"")
A12: DAILY TOTALS | E12: =SUM(E6:E11) -> 0 | F12: =SUM(F6:F11) -> 0 | G12: =SUM(G6:G11) -> 0 | H12: =SUM(H6:H11) -> 0 | I12: =SUM(I6:I11) -> 0 | J12: =IF(E12=0,"—",IF(E12<TgtKcal-400,"▼ Kurang sangat",IF(E12<=TgtKcal,"✓ Ikut target",IF(E12<=TgtKcal+250,"~ Dekat","▲ Lebih")))) -> —
A13: TARGET | E13: =TgtKcal -> 1500 | F13: =TgtPro -> 90 | G13: =TgtCarb -> 130 | H13: =TgtFat -> 50 | I13: =TgtFib -> 30
A14: VARIANCE (%) | E14: =IF(E12=0,"",(E12-E13)/E13) | F14: =IF(F12=0,"",(F12-F13)/F13) | G14: =IF(G12=0,"",(G12-G13)/G13) | H14: =IF(H12=0,"",(H12-H13)/H13) | I14: =IF(I12=0,"",(I12-I13)/I13)
A16: TUESDAY · SELASA
A17: Meal | B17: Time | C17: Food Item | D17: Servings (×) | E17: Kcal | F17: Protein (g) | G17: Carbs (g) | H17: Fat (g) | I17: Fibre (g) | J17: Notes
A18: Breakfast / Sarapan | E18: =IFERROR(INDEX(FoodKcal,MATCH(C18,FoodName,0))*D18,"") | F18: =IFERROR(INDEX(FoodPro,MATCH(C18,FoodName,0))*D18,"") | G18: =IFERROR(INDEX(FoodCarb,MATCH(C18,FoodName,0))*D18,"") | H18: =IFERROR(INDEX(FoodFat,MATCH(C18,FoodName,0))*D18,"") | I18: =IFERROR(INDEX(FoodFib,MATCH(C18,FoodName,0))*D18,"")
A19: Mid-Morning Snack / Snek Pagi | E19: =IFERROR(INDEX(FoodKcal,MATCH(C19,FoodName,0))*D19,"") | F19: =IFERROR(INDEX(FoodPro,MATCH(C19,FoodName,0))*D19,"") | G19: =IFERROR(INDEX(FoodCarb,MATCH(C19,FoodName,0))*D19,"") | H19: =IFERROR(INDEX(FoodFat,MATCH(C19,FoodName,0))*D19,"") | I19: =IFERROR(INDEX(FoodFib,MATCH(C19,FoodName,0))*D19,"")
A20: Lunch / Tengahari | E20: =IFERROR(INDEX(FoodKcal,MATCH(C20,FoodName,0))*D20,"") | F20: =IFERROR(INDEX(FoodPro,MATCH(C20,FoodName,0))*D20,"") | G20: =IFERROR(INDEX(FoodCarb,MATCH(C20,FoodName,0))*D20,"") | H20: =IFERROR(INDEX(FoodFat,MATCH(C20,FoodName,0))*D20,"") | I20: =IFERROR(INDEX(FoodFib,MATCH(C20,FoodName,0))*D20,"")
A21: Afternoon Snack / Snek Petang | E21: =IFERROR(INDEX(FoodKcal,MATCH(C21,FoodName,0))*D21,"") | F21: =IFERROR(INDEX(FoodPro,MATCH(C21,FoodName,0))*D21,"") | G21: =IFERROR(INDEX(FoodCarb,MATCH(C21,FoodName,0))*D21,"") | H21: =IFERROR(INDEX(FoodFat,MATCH(C21,FoodName,0))*D21,"") | I21: =IFERROR(INDEX(FoodFib,MATCH(C21,FoodName,0))*D21,"")
A22: Dinner / Malam | E22: =IFERROR(INDEX(FoodKcal,MATCH(C22,FoodName,0))*D22,"") | F22: =IFERROR(INDEX(FoodPro,MATCH(C22,FoodName,0))*D22,"") | G22: =IFERROR(INDEX(FoodCarb,MATCH(C22,FoodName,0))*D22,"") | H22: =IFERROR(INDEX(FoodFat,MATCH(C22,FoodName,0))*D22,"") | I22: =IFERROR(INDEX(FoodFib,MATCH(C22,FoodName,0))*D22,"")
A23: Evening (optional) / Malam (pilihan) | E23: =IFERROR(INDEX(FoodKcal,MATCH(C23,FoodName,0))*D23,"") | F23: =IFERROR(INDEX(FoodPro,MATCH(C23,FoodName,0))*D23,"") | G23: =IFERROR(INDEX(FoodCarb,MATCH(C23,FoodName,0))*D23,"") | H23: =IFERROR(INDEX(FoodFat,MATCH(C23,FoodName,0))*D23,"") | I23: =IFERROR(INDEX(FoodFib,MATCH(C23,FoodName,0))*D23,"")
A24: DAILY TOTALS | E24: =SUM(E18:E23) -> 0 | F24: =SUM(F18:F23) -> 0 | G24: =SUM(G18:G23) -> 0 | H24: =SUM(H18:H23) -> 0 | I24: =SUM(I18:I23) -> 0 | J24: =IF(E24=0,"—",IF(E24<TgtKcal-400,"▼ Kurang sangat",IF(E24<=TgtKcal,"✓ Ikut target",IF(E24<=TgtKcal+250,"~ Dekat","▲ Lebih")))) -> —
A25: TARGET | E25: =TgtKcal -> 1500 | F25: =TgtPro -> 90 | G25: =TgtCarb -> 130 | H25: =TgtFat -> 50 | I25: =TgtFib -> 30
A26: VARIANCE (%) | E26: =IF(E24=0,"",(E24-E25)/E25) | F26: =IF(F24=0,"",(F24-F25)/F25) | G26: =IF(G24=0,"",(G24-G25)/G25) | H26: =IF(H24=0,"",(H24-H25)/H25) | I26: =IF(I24=0,"",(I24-I25)/I25)
A28: WEDNESDAY · RABU
A29: Meal | B29: Time | C29: Food Item | D29: Servings (×) | E29: Kcal | F29: Protein (g) | G29: Carbs (g) | H29: Fat (g) | I29: Fibre (g) | J29: Notes
A30: Breakfast / Sarapan | E30: =IFERROR(INDEX(FoodKcal,MATCH(C30,FoodName,0))*D30,"") | F30: =IFERROR(INDEX(FoodPro,MATCH(C30,FoodName,0))*D30,"") | G30: =IFERROR(INDEX(FoodCarb,MATCH(C30,FoodName,0))*D30,"") | H30: =IFERROR(INDEX(FoodFat,MATCH(C30,FoodName,0))*D30,"") | I30: =IFERROR(INDEX(FoodFib,MATCH(C30,FoodName,0))*D30,"")
A31: Mid-Morning Snack / Snek Pagi | E31: =IFERROR(INDEX(FoodKcal,MATCH(C31,FoodName,0))*D31,"") | F31: =IFERROR(INDEX(FoodPro,MATCH(C31,FoodName,0))*D31,"") | G31: =IFERROR(INDEX(FoodCarb,MATCH(C31,FoodName,0))*D31,"") | H31: =IFERROR(INDEX(FoodFat,MATCH(C31,FoodName,0))*D31,"") | I31: =IFERROR(INDEX(FoodFib,MATCH(C31,FoodName,0))*D31,"")
A32: Lunch / Tengahari | E32: =IFERROR(INDEX(FoodKcal,MATCH(C32,FoodName,0))*D32,"") | F32: =IFERROR(INDEX(FoodPro,MATCH(C32,FoodName,0))*D32,"") | G32: =IFERROR(INDEX(FoodCarb,MATCH(C32,FoodName,0))*D32,"") | H32: =IFERROR(INDEX(FoodFat,MATCH(C32,FoodName,0))*D32,"") | I32: =IFERROR(INDEX(FoodFib,MATCH(C32,FoodName,0))*D32,"")
A33: Afternoon Snack / Snek Petang | E33: =IFERROR(INDEX(FoodKcal,MATCH(C33,FoodName,0))*D33,"") | F33: =IFERROR(INDEX(FoodPro,MATCH(C33,FoodName,0))*D33,"") | G33: =IFERROR(INDEX(FoodCarb,MATCH(C33,FoodName,0))*D33,"") | H33: =IFERROR(INDEX(FoodFat,MATCH(C33,FoodName,0))*D33,"") | I33: =IFERROR(INDEX(FoodFib,MATCH(C33,FoodName,0))*D33,"")
A34: Dinner / Malam | E34: =IFERROR(INDEX(FoodKcal,MATCH(C34,FoodName,0))*D34,"") | F34: =IFERROR(INDEX(FoodPro,MATCH(C34,FoodName,0))*D34,"") | G34: =IFERROR(INDEX(FoodCarb,MATCH(C34,FoodName,0))*D34,"") | H34: =IFERROR(INDEX(FoodFat,MATCH(C34,FoodName,0))*D34,"") | I34: =IFERROR(INDEX(FoodFib,MATCH(C34,FoodName,0))*D34,"")
A35: Evening (optional) / Malam (pilihan) | E35: =IFERROR(INDEX(FoodKcal,MATCH(C35,FoodName,0))*D35,"") | F35: =IFERROR(INDEX(FoodPro,MATCH(C35,FoodName,0))*D35,"") | G35: =IFERROR(INDEX(FoodCarb,MATCH(C35,FoodName,0))*D35,"") | H35: =IFERROR(INDEX(FoodFat,MATCH(C35,FoodName,0))*D35,"") | I35: =IFERROR(INDEX(FoodFib,MATCH(C35,FoodName,0))*D35,"")
A36: DAILY TOTALS | E36: =SUM(E30:E35) -> 0 | F36: =SUM(F30:F35) -> 0 | G36: =SUM(G30:G35) -> 0 | H36: =SUM(H30:H35) -> 0 | I36: =SUM(I30:I35) -> 0 | J36: =IF(E36=0,"—",IF(E36<TgtKcal-400,"▼ Kurang sangat",IF(E36<=TgtKcal,"✓ Ikut target",IF(E36<=TgtKcal+250,"~ Dekat","▲ Lebih")))) -> —
A37: TARGET | E37: =TgtKcal -> 1500 | F37: =TgtPro -> 90 | G37: =TgtCarb -> 130 | H37: =TgtFat -> 50 | I37: =TgtFib -> 30
A38: VARIANCE (%) | E38: =IF(E36=0,"",(E36-E37)/E37) | F38: =IF(F36=0,"",(F36-F37)/F37) | G38: =IF(G36=0,"",(G36-G37)/G37) | H38: =IF(H36=0,"",(H36-H37)/H37) | I38: =IF(I36=0,"",(I36-I37)/I37)
A40: THURSDAY · KHAMIS
A41: Meal | B41: Time | C41: Food Item | D41: Servings (×) | E41: Kcal | F41: Protein (g) | G41: Carbs (g) | H41: Fat (g) | I41: Fibre (g) | J41: Notes
A42: Breakfast / Sarapan | E42: =IFERROR(INDEX(FoodKcal,MATCH(C42,FoodName,0))*D42,"") | F42: =IFERROR(INDEX(FoodPro,MATCH(C42,FoodName,0))*D42,"") | G42: =IFERROR(INDEX(FoodCarb,MATCH(C42,FoodName,0))*D42,"") | H42: =IFERROR(INDEX(FoodFat,MATCH(C42,FoodName,0))*D42,"") | I42: =IFERROR(INDEX(FoodFib,MATCH(C42,FoodName,0))*D42,"")
A43: Mid-Morning Snack / Snek Pagi | E43: =IFERROR(INDEX(FoodKcal,MATCH(C43,FoodName,0))*D43,"") | F43: =IFERROR(INDEX(FoodPro,MATCH(C43,FoodName,0))*D43,"") | G43: =IFERROR(INDEX(FoodCarb,MATCH(C43,FoodName,0))*D43,"") | H43: =IFERROR(INDEX(FoodFat,MATCH(C43,FoodName,0))*D43,"") | I43: =IFERROR(INDEX(FoodFib,MATCH(C43,FoodName,0))*D43,"")
...

Sheet Food Database
A1: COMPREHENSIVE FOOD DATABASE — MACRONUTRIENT REFERENCE
A2: All values per standard serving. Weigh food raw for maximum accuracy. Database validated against Malaysian Food Composition Tables & USDA SR Legacy.
A3: Category | B3: Food Item | C3: Serving Size | D3: Kcal | E3: Protein (g) | F3: Carbs (g) | G3: Fat (g) | H3: Fibre (g) | I3: Glycemic Load | J3: Notes
A4: SALMON & FISH | B4: Atlantic Salmon, raw | C4: 150g fillet | D4: 310 | E4: 33 | F4: 0 | G4: 18 | H4: 0 | I4: 0 | J4: Rich in EPA/DHA (~1.5g/150g). Grill/bake/steam preferred.
A5: SALMON & FISH | B5: Salmon, canned in water | C5: 1 tin (150g drained) | D5: 150 | E5: 20 | F5: 0 | G5: 7 | H5: 0 | I5: 0 | J5: Emergency protein. Drain thoroughly.
A6: SALMON & FISH | B6: Salmon Head Curry (light santan) | C6: 1 serving (~300g) | D6: 400 | E6: 28 | F6: 8 | G6: 28 | H6: 2 | I6: 3 | J6: Cheapest cut. Request less santan at stall.
A7: SALMON & FISH | B7: Ikan Kembung, grilled | C7: 1 fish (~150g) | D7: 180 | E7: 25 | F7: 0 | G7: 8 | H7: 0 | I7: 0 | J7: High omega-3. RM3–5 per fish at pasar.
A8: SALMON & FISH | B8: Ikan Siakap, steamed | C8: 150g fillet | D8: 170 | E8: 28 | F8: 0 | G8: 6 | H8: 0 | I8: 0 | J8: Lean white fish. Steam with ginger & soy.
A9: SALMON & FISH | B9: Sardines in tomato sauce | C9: 1 tin (150g) | D9: 140 | E9: 18 | F9: 4 | G9: 6 | H9: 2 | I9: 2 | J9: Calcium from edible bones. Budget-friendly.
A10: POULTRY | B10: Chicken Breast, skinless, raw | C10: 150g | D10: 165 | E10: 31 | F10: 0 | G10: 3.6 | H10: 0 | I10: 0 | J10: Highest protein-to-kcal ratio. Marinate overnight.
A11: POULTRY | B11: Chicken Breast, grilled | C11: 150g | D11: 250 | E11: 46 | F11: 0 | G11: 5 | H11: 0 | I11: 0 | J11: Post-cooking weight ~20% less than raw.
A12: POULTRY | B12: Ayam Percik, grilled, skin removed | C12: 1 piece (~150g) | D12: 280 | E12: 30 | F12: 4 | G12: 15 | H12: 1 | I12: 2 | J12: Remove skin = save ~80 kcal.
A13: POULTRY | B13: Chicken Thigh, skinless, raw | C13: 150g | D13: 195 | E13: 26 | F13: 0 | G13: 9 | H13: 0 | I13: 0 | J13: More flavour than breast; slightly higher fat.
A14: POULTRY | B14: Whole Egg, boiled | C14: 1 large (50g) | D14: 78 | E14: 6 | F14: 0.6 | G14: 5.3 | H14: 0 | I14: 0 | J14: Boil 6 on Sunday. Store peeled in fridge.
A15: POULTRY | B15: Egg White only | C15: 1 large (33g) | D15: 17 | E15: 3.6 | F15: 0.2 | G15: 0.1 | H15: 0 | I15: 0 | J15: Pure protein. Use with 1 whole egg for balance.
... A72: TREATS & FLEXIBLE FOODS | B72: Cendol, reduced sugar | C72: 1 bowl | D72: 200 | E72: 4 | F72: 35 | G72: 5 | H72: 1 | I72: 15 | J72: Request 'kurang gula, kurang santan'.
A91: NOTE: Use this database to populate your Weekly Meal Schedule. For foods not listed, reference the Malaysian Food Composition Database (MFCDB) or USDA FoodData Central. Always prioritise whole, minimally processed foods.

Sheet Recipe Collection
A1: RECIPE COLLECTION — STRUCTURED MEAL PREPARATION
A2: All recipes designed for ≤20 min active time. Macros calculated per serving. Ingredients available at Giant Setiawangsa or Pasar Keramat.
A4: SAMBAL SALMON BAKAR | 15 min | 350 kcal | P:33g C:8g F:18g Fibre:2g
A5: INGREDIENTS: 150g salmon fillet | 1 tbsp sambal tumis | ½ tsp turmeric powder | ¼ tsp sea salt | 1 limau kasturi | 1 cup ulam (served)
A6: 1. Pat salmon dry with paper towel. Rub turmeric and salt evenly. 2. Spread sambal tumis on flesh side. 3. Air-fry at 200°C for 12 min or oven-bake 200°C for 14 min. 4. Rest 2 min. Squeeze limau kasturi over top. 5. Serve with 1 cup steamed ulam and ½ cup brown rice.
A7: CHEF'S NOTE: Grill, don't fry. Frozen Norwegian fillet is 30–40% cheaper than fresh and nutritionally equivalent.
A9: LEMON BUTTER PAN-SEARED SALMON | 12 min | 330 kcal | P:33g C:2g F:20g Fibre:0g
A10: INGREDIENTS: 150g salmon fillet | 1 tsp unsalted butter | 1 clove garlic, minced | ½ lemon (juice) | Black pepper | Parsley (optional)
A11: 1. Pat salmon completely dry — this is critical for crispy skin. 2. Heat pan on medium-high. Place salmon skin-side down. Do not move for 5 min. 3. Flip carefully. Cook 3 min on flesh side. 4. Remove from heat. Add butter, garlic, lemon juice to pan. Swirl 30 seconds. 5. Pour over salmon. Season with black pepper.
A12: CHEF'S NOTE: Crispy skin trick: the drier the surface, the better the Maillard reaction. Use a heavy-bottomed pan.
A14: SETIAWANGSA SUNSHINE BOWL | 10 min | 380 kcal | P:35g C:28g F:16g Fibre:8g
A15: INGREDIENTS: 100g mixed salad greens | 100g cucumber, sliced | 100g cherry tomatoes | 150g salmon (flaked, fresh or canned) | ½ avocado | 1 tbsp olive oil | 1 tbsp lemon juice | Pinch sea salt
... A45: • STORAGE: Fresh salmon — use within 24 hours of purchase. Cooked salmon — refrigerate up to 48 hours. Frozen salmon — use within 3 months for optimal quality.

Sheet Body Composition
A1: BODY COMPOSITION & PROGRESS MONITORING
A2: Weigh once weekly. Same day, same time, same conditions. Track trends, not single data points. Body weight fluctuates 1–3% daily due to hydration, sodium, and glycogen.
A4: WEEKLY WEIGHT & BODY COMPOSITION LOG | H4: ANTHROPOMETRIC MEASUREMENTS
A5: Week | B5: Date | C5: Weight (kg) | D5: 7-Day Avg (kg) | E5: Change (kg) | F5: Change (%) | H5: Week | I5: Waist (cm) | J5: Hip (cm)
A6: Week 1 | E6: ="—" -> — | F6: ="—" -> — | H6: W1
A7: Week 2 | E7: =IF(OR(C7="",C6=""),"",ROUND(C7-C6,1)) | F7: =IF(OR(C7="",C6=""),"",(C7-C6)/C6) | H7: W2
A8: Week 3 | E8: =IF(OR(C8="",C7=""),"",ROUND(C8-C7,1)) | F8: =IF(OR(C8="",C7=""),"",(C8-C7)/C7) | H8: W3
A9: Week 4 | E9: =IF(OR(C9="",C8=""),"",ROUND(C9-C8,1)) | F9: =IF(OR(C9="",C8=""),"",(C9-C8)/C8) | H9: W4
A10: Week 5 | E10: =IF(OR(C10="",C9=""),"",ROUND(C10-C9,1)) | F10: =IF(OR(C10="",C9=""),"",(C10-C9)/C9) | H10: W5
A11: Week 6 | E11: =IF(OR(C11="",C10=""),"",ROUND(C11-C10,1)) | F11: =IF(OR(C11="",C10=""),"",(C11-C10)/C10) | H11: W6
A12: Week 7 | E12: =IF(OR(C12="",C11=""),"",ROUND(C12-C11,1)) | F12: =IF(OR(C12="",C11=""),"",(C12-C11)/C11) | H12: W7
A13: Week 8 | E13: =IF(OR(C13="",C12=""),"",ROUND(C13-C12,1)) | F13: =IF(OR(C13="",C12=""),"",(C13-C12)/C12) | H13: W8
A14: Week 9 | E14: =IF(OR(C14="",C13=""),"",ROUND(C14-C13,1)) | F14: =IF(OR(C14="",C13=""),"",(C14-C13)/C13) | H14: W9
A15: Week 10 | E15: =IF(OR(C15="",C14=""),"",ROUND(C15-C14,1)) | F15: =IF(OR(C15="",C14=""),"",(C15-C14)/C14) | H15: W10
A16: Week 11 | E16: =IF(OR(C16="",C15=""),"",ROUND(C16-C15,1)) | F16: =IF(OR(C16="",C15=""),"",(C16-C15)/C15) | H16: W11
A17: Week 12 | E17: =IF(OR(C17="",C16=""),"",ROUND(C17-C16,1)) | F17: =IF(OR(C17="",C16=""),"",(C17-C16)/C16) | H17: W12
A20: DETAILED MEASUREMENTS (Monthly) | G20: NON-SCALE PERFORMANCE INDICATORS
A21: Measurement | B21: Baseline | C21: Week 4 | D21: Week 8 | E21: Week 12 | G21: Clothing fit — ease of fastening, reduced tightness | I21: Baseline | J21: Week 12
A22: Chest (cm) | G22: Stair climbing endurance — breathlessness reduction | I22: Baseline | J22: Week 12
A23: Mid-arm, relaxed (cm) | G23: Sleep quality — onset latency, nocturnal awakenings | I23: Baseline | J23: Week 12
A24: Mid-arm, flexed (cm) | G24: Skin condition — clarity, hydration, reduced inflammation | I24: Baseline | J24: Week 12
A25: Waist, narrowest (cm) | G25: Sustained energy — afternoon fatigue reduction | I25: Baseline | J25: Week 12
A26: Waist, navel level (cm) | G26: Sugar craving frequency — intensity and occurrence | I26: Baseline | J26: Week 12
A27: Hips, widest (cm) | G27: Digestive regularity — bloating reduction, transit time | I27: Baseline | J27: Week 12
A28: Mid-thigh (cm) | G28: Mood stability — irritability, anxiety, general wellbeing | I28: Baseline | J28: Week 12
A29: Calf (cm) | G29: Physical performance — walking pace, exercise capacity | I29: Baseline | J29: Week 12
A30: Body Fat % (caliper/scale) | G30: Recovery rate — post-exercise soreness duration | I30: Baseline | J30: Week 12
A31: Resting Heart Rate (bpm)
A34: PROGRESS PHOTOGRAPHY LOG
A35: Week | B35: Date | C35: Front View | D35: Side View | E35: Back View | F35: Lighting | G35: Notes
A36: Week 1
A37: Week 4
A38: Week 7
A39: Week 10
A40: Week 13
A42: PHOTO PROTOCOL: Same location, same lighting (natural front-facing), same clothing (fitted, minimal), same time of day. Take front, side (dominant), and back views. Do not rely on mirror selfies — use timer or assistance.

Sheet Shopping & Meal Prep
A1: PROCUREMENT & MEAL PREPARATION SYSTEM
A2: Strategic sourcing within Setiawangsa area. Batch preparation reduces decision fatigue and improves adherence by 40–60% (Arshad et al., 2022).
A4: VENDOR DIRECTORY — SETIAWANGSA AREA | F4: WEEKLY PROCUREMENT CHECKLIST
A5: Vendor | B5: Operating Hours | C5: Location | D5: Primary Strengths | F5: Category | G5: Item | H5: Qty | I5: Est. Cost (RM) | J5: Vendor | K5: Priority
A6: ST Rosyam Mart Setiawangsa | B6: 24 hours | C6: Jln Setiawangsa 8 | D6: Late-night availability. Basic pantry staples. | F6: PROTEIN | G6: Salmon fillet, frozen, Norwegian | H6: 6 portions (900g) | I6: 45–55 | J6: Giant / AEON | K6: ESSENTIAL
A7: Giant Setiawangsa | B7: 7am–10pm | C7: Jln Setiawangsa 8 | D7: Best value frozen salmon, brown rice, oats, bulk items. | F7: PROTEIN | G7: Canned salmon in water | H7: 2 tins | I7: 16 | J7: Giant | K7: ESSENTIAL
A8: AEON AU2 Setiawangsa | B8: 10am–10pm | C8: AEON Mall AU2 | D8: Superior fresh fish counter. Request custom salmon portions. | F8: PROTEIN | G8: Chicken breast, skinless | H8: 500g | I8: 12 | J8: Pasar Keramat | K8: ESSENTIAL
A9: Pasar Basah Dato Keramat | B9: 5am–7pm | C9: Lrg Keramat Dalam 8 | D9: Freshest produce & fish. Lowest prices. Arrive before 9am. | F9: PROTEIN | G9: Whole eggs, grade A | H9: 1 dozen | I9: 8 | J9: Any | K9: ESSENTIAL
A10: Pasar Tani AU1 Keramat | B10: Wed 8–11am ONLY | C10: Jln AU 1A/4A | D10: Cheapest ulam, herbs, and seasonal fruit. Wednesday exclusive. | F10: PROTEIN | G10: Tempeh | H10: 2 blocks | I10: 4 | J10: Pasar Keramat | K10: ESSENTIAL
A11: Village Grocer Melawati | B11: 10am–10pm | C11: Melawati Mall | D11: Premium Norwegian salmon, Greek yogurt, organic produce. | F11: PROTEIN | G11: Firm tofu | H11: 1 pack (400g) | I11: 3 | J11: Any | K11: ESSENTIAL
A12: Mydin Wholesale | B12: 9am–10pm | C12: AU3 Keramat | D12: Bulk dry goods at wholesale pricing. Rice, oats, spices. | F12: PROTEIN | G12: Greek yogurt, plain, low-fat | H12: 1 tub (500g) | I12: 12 | J12: Village Grocer / AEON | K12: ESSENTIAL
F13: PROTEIN | G13: Skim milk | H13: 1L | I13: 6 | J13: Any | K13: RECOMMENDED
F14: CARBS | G14: Brown rice | H14: 1kg | I14: 8 | J14: Giant / Mydin | K14: ESSENTIAL
A15: BATCH PREPARATION SCHEDULE — SUNDAY PROTOCOL | F15: CARBS | G15: Rolled oats | H15: 1kg | I15: 10 | J15: Giant / Mydin | K15: ESSENTIAL
A16: Time Block | B16: Task | C16: Duration | D16: Storage | F16: CARBS | G16: Wholemeal bread | H16: 1 loaf | I16: 5 | J16: Any | K16: ESSENTIAL
A17: 08:00–08:30 | B17: Defrost salmon portions (if frozen). Wash & dry all vegetables. | C17: 30 min | D17: — | F17: CARBS | G17: Sweet potatoes | H17: 1kg | I17: 5 | J17: Pasar Keramat | K17: RECOMMENDED
A18: 08:30–09:00 | B18: Boil 6 eggs. Cook 3 cups brown rice (yields 6 portions). | C18: 30 min | D18: Eggs: fridge 7 days. Rice: fridge 3 days. | F18: VEGETABLES | G18: Mixed salad greens | H18: 2 bags | I18: 10 | J18: AEON / Village Grocer | K18: ESSENTIAL
A19: 09:00–09:45 | B19: Marinate chicken breast (soy, ginger, garlic). Portion salmon into 150g bags. | C19: 45 min | D19: Marinated chicken: fridge 24h. Salmon: freeze flat. | F19: VEGETABLES | G19: Cucumber & tomato | H19: 1kg combined | I19: 5 | J19: Pasar Keramat | K19: ESSENTIAL
A20: 09:45–10:30 | B20: Steam broccoli & mixed vegetables. Blanch 2 min only. | C20: 45 min | D20: Fridge 4 days. Reheat by steaming. | F20: VEGETABLES | G20: Broccoli | H20: 500g | I20: 4 | J20: Any | K20: RECOMMENDED
A21: 10:30–11:00 | B21: Wash & spin salad greens. Store with paper towel in airtight container. | C21: 30 min | D21: Fridge 5 days. Paper towel absorbs moisture. | F21: VEGETABLES | G21: Ulam pack (pegaga, pucuk paku, etc.) | H21: 1 pack | I21: 3 | J21: Pasar Tani | K21: ESSENTIAL
A22: 11:00–11:30 | B22: Prepare overnight oats (3 jars): 40g oats + 150g yogurt + fruit. | C22: 30 min | D22: Fridge 3 days. Grab-and-go breakfast. | F22: VEGETABLES | G22: Ginger & garlic | H22: 200g each | I22: 4 | J22: Any | K22: ESSENTIAL
A23: 11:30–12:00 | B23: Portion nuts & snacks into small containers (15 almonds each). | C23: 30 min | D23: Room temp. Prevents overeating from bulk bags. | F23: VEGETABLES | G23: Spring onion & limau kasturi | H23: 1 bunch / 10 pcs | I23: 5 | J23: Any | K23: ESSENTIAL
A24: 12:00–12:30 | B24: Clean kitchen. Review Weekly Meal Schedule. Adjust based on social plans. | C24: 30 min | D24: — | F24: FRUIT | G24: Apples | H24: 5 pcs | I24: 8 | J24: Any | K24: ESSENTIAL
F25: FRUIT | G25: Bananas | H25: 1 comb | I25: 5 | J25: Any | K25: ESSENTIAL
A26: FOOD SAFETY & STORAGE GUIDELINES | F26: FRUIT | G26: Papaya or watermelon | H26: 1 medium / ¼ fruit | I26: 6 | J26: Pasar Keramat | K26: RECOMMENDED
A27: Food Item | B27: Refrigerator (4°C) | C27: Freezer (-18°C) | D27: Reheating Method | F27: FRUIT | G27: Avocado | H27: 2 pcs | I27: 10 | J27: Village Grocer | K27: RECOMMENDED
A28: Cooked salmon | B28: 48 hours | C28: 2 months | D28: Steam 5 min or microwave 60 sec covered | F28: PANTRY | G28: Almonds, raw | H28: 200g | I28: 12 | J28: Giant | K28: RECOMMENDED
A29: Cooked chicken | B29: 48 hours | C29: 3 months | D29: Oven 180°C 10 min or pan with splash of water | F29: PANTRY | G29: Sambal tumis (bottled) | H29: 1 jar | I29: 8 | J29: Any | K29: ESSENTIAL
A30: Boiled eggs | B30: 7 days | C30: Not recommended | D30: Room temp or warm water 3 min | F30: PANTRY | G30: Light soy sauce | H30: 1 bottle | I30: 5 | J30: Any | K30: ESSENTIAL
A31: Cooked rice | B31: 3 days | C31: 1 month | D31: Steam or microwave with damp cloth | F31: PANTRY | G31: Extra virgin olive oil | H31: 250ml | I31: 15 | J31: Giant | K31: ESSENTIAL
A32: Steamed vegetables | B32: 4 days | C32: 2 months | D32: Steam 3 min. Avoid microwave — texture degrades. | F32: PANTRY | G32: Turmeric powder & black pepper | H32: 50g each | I32: 4 | J32: Any | K32: ESSENTIAL
A33: Salad greens (washed) | B33: 5 days | C33: Not recommended | D33: Serve cold. Do not heat. | F33: PANTRY | G33: Sesame oil | H33: 100ml | I33: 6 | J33: Any | K33: RECOMMENDED
A34: Marinated raw meat | B34: 24 hours | C34: 3 months | D34: Thaw overnight in fridge. Never at room temp. | F34: ESTIMATED WEEKLY BUDGET
A35: Overnight oats | B35: 3 days | C35: Not recommended | D35: Serve cold. Add fresh fruit before eating. | F35: Category | G35: Est. Weekly Cost (RM) | H35: % of Total
F36: Protein (salmon, chicken, eggs, dairy) | G36: 106–116 | H36: ~45%
F37: Carbohydrates (rice, oats, bread, potatoes) | G37: 23 | H37: ~10%
F38: Vegetables & Fresh Produce | G38: 31 | H38: ~13%
F39: Fruit | G39: 29 | H39: ~12%
F40: Pantry & Condiments | G40: 63 | H40: ~26%
F41: TOTAL (Essential items only) | G41: ~170–180 | H41: 100%
...

Sheet Supplement & Hydration
A1: MICRONUTRIENT, SUPPLEMENT & HYDRATION PROTOCOL
A2: Food-first approach. Supplements address gaps, not replace whole foods. Consult a registered dietitian before introducing new supplements.
A4: EVIDENCE-BASED SUPPLEMENT RECOMMENDATIONS | F4: DAILY HYDRATION MONITORING
A5: Supplement | B5: Recommended Dose | C5: Timing | D5: Purpose | E5: Food Source Alternative | F5: Time | G5: Beverage | H5: Volume (ml) | I5: Cumulative (ml) | J5: Notes
A6: Omega-3 (EPA+DHA) | B6: 1,000–2,000 mg/day | C6: With main meal | D6: Anti-inflammatory, cardiovascular, cognitive support | E6: 150g salmon (3–4x/week) | F6: 06:00–07:00 | G6: Water (upon waking) | H6: 500 | I6: =H6 -> 500 | J6: Rehydrate after 7–8h fast
A7: Vitamin D3 | B7: 1,000–2,000 IU/day | C7: Morning, with fat | D7: Bone health, immune function, mood regulation | E7: Sun exposure 15 min (10am–3pm) | F7: 08:00–09:00 | G7: Black coffee / Teh O | H7: 250 | I7: =SUM($H$6:H7) -> 750 | J7: Caffeine: mild diuretic, net hydration positive
A8: Magnesium | B8: 200–400 mg/day (bisglycinate) | C8: Evening, before bed | D8: Muscle relaxation, sleep quality, insulin sensitivity | E8: Pumpkin seeds, dark chocolate, leafy greens | F8: 10:00–11:00 | G8: Water | H8: 250 | I8: =SUM($H$6:H8) -> 1000 | J8: —
A9: Probiotics | B9: 10–50 billion CFU, multi-strain | C9: Morning, empty stomach | D9: Gut microbiome diversity, immune modulation | E9: Greek yogurt, kimchi, tempeh | F9: 12:00–13:00 | G9: Water (before lunch) | H9: 250 | I9: =SUM($H$6:H9) -> 1250 | J9: Promotes satiety, aids digestion
A10: Collagen Peptides | B10: 10g/day | C10: Morning or post-workout | D10: Skin elasticity, joint support (mixed evidence) | E10: Salmon skin, bone broth, chicken feet | F10: 14:00–15:00 | G10: Green tea / Water | H10: 250 | I10: =SUM($H$6:H10) -> 1500 | J10: —
A11: Multivitamin | B11: 1 tablet (gender-specific) | C11: With breakfast | D11: Insurance against micronutrient gaps | E11: Varied whole-food diet | F11: 16:00–17:00 | G11: Water | H11: 250 | I11: =SUM($H$6:H11) -> 1750 | J11: —
A12: Creatine Monohydrate | B12: 3–5g/day | C12: Any time, consistent | D12: Cognitive support, muscle phosphocreatine stores | E12: Red meat, fish (1kg beef = ~5g creatine) | F12: 18:00–19:00 | G12: Water (before dinner) | H12: 250 | I12: =SUM($H$6:H12) -> 2000 | J12: —
A13: Iron (if deficient) | B13: Per blood test results | C13: With vitamin C, away from calcium | D13: Oxygen transport, energy metabolism | E13: Red meat, spinach, lentils + vitamin C | F13: 20:00–21:00 | G13: Water / Herbal tea | H13: 250 | I13: =SUM($H$6:H13) -> 2250 | J13: Limit fluids 1h before bed to reduce nocturia
A14: B-Complex | B14: 1 tablet | C14: With breakfast | D14: Energy metabolism, neurological function | E14: Eggs, dairy, whole grains, leafy greens | F14: Exercise + | G14: Additional water | H14: 500–1000 | I14: 2750–3250 | J14: Add 500ml per 30 min moderate activity
A16: DAILY MICRONUTRIENT TARGETS — FOOD-FIRST CHECKLIST | F16: CAFFEINE MANAGEMENT PROTOCOL
A17: Nutrient | B17: Daily Target | C17: Primary Food Sources | D17: Check | F17: Beverage | G17: Serving | H17: Caffeine (mg) | I17: Recommended Max
A18: Vitamin A | B18: 700 mcg RAE | C18: Carrot, spinach, papaya, eggs | D18: ☐ | F18: Black Coffee | G18: 1 cup (240ml) | H18: 95 | I18: 3 cups/day
A19: Vitamin C | B19: 75 mg | C19: Guava, orange, broccoli, tomato | D19: ☐ | F19: Teh Tarik | G19: 1 cup (300ml) | H19: 50 | I19: 2 cups/day
A20: Vitamin D | B20: 15 mcg (600 IU) | C20: Salmon, egg yolk, sun exposure | D20: ☐ | F20: Green Tea | G20: 1 cup (240ml) | H20: 35 | I20: 4 cups/day
A21: Vitamin E | B21: 15 mg | C21: Almonds, sunflower seeds, avocado | D21: ☐ | F21: Milo | G21: 1 cup (240ml) | H21: 5 | I21: No limit (sugar is the concern)
A22: Vitamin K | B22: 90 mcg | C22: Ulam, spinach, broccoli, spring onion | D22: ☐ | F22: Energy Drinks | G22: 1 can (250ml) | H22: 80 | I22: AVOID — sugar + caffeine spike
A23: Calcium | B23: 1,000 mg | C23: Greek yogurt, skim milk, tofu, tempeh | D23: ☐ | F23: Pre-workout | G23: 1 scoop | H23: 150–300 | I23: Only if training; not for daily use
A24: Iron | B24: 18 mg | C24: Red meat, spinach, lentils + vitamin C | D24: ☐
A25: Magnesium | B25: 310 mg | C25: Pumpkin seeds, dark chocolate, oats | D25: ☐ | F25: CAFFEINE CUT-OFF: No caffeine after 2:00 PM to preserve sleep architecture. Caffeine half-life is 5–6 hours; quarter-life is 10–12 hours.
A26: Zinc | B26: 8 mg | C26: Beef, pumpkin seeds, shellfish | D26: ☐
A27: Potassium | B27: 2,600 mg | C27: Banana, sweet potato, spinach, tomato | D27: ☐
A28: Omega-3 (EPA+DHA) | B28: 1,000 mg | C28: Salmon (3–4x/week), sardines, walnuts | D28: ☐
A29: Fibre | B29: 30 g | C29: Oats, brown rice, vegetables, fruit, chia | D29: ☐

Sheet Methodology & References
A1: METHODOLOGY, DISCLAIMERS & EVIDENCE BASE
A3: PROGRAMME METHODOLOGY
A4: 1. ENERGY BALANCE FRAMEWORK: This programme operates on the principle of sustained negative energy balance. A deficit of 300–500 kcal/day below Total Daily Energy Expenditure (TDEE) produces a fat loss rate of 0.4–0.6 kg/week. This rate minimises adaptive thermogenesis, preserves lean body mass, and supports hormonal homeostasis. Faster rates (>1 kg/week) increase risk of gallstone formation, muscle catabolism, and menstrual disruption in females.
A6: 2. PROTEIN THRESHOLD: Protein intake is set at 1.4–1.6 g/kg target body weight (90g/day for 55kg goal). This exceeds the RDA (0.8 g/kg) and aligns with sports nutrition consensus for body recomposition during caloric restriction. Higher protein preserves muscle protein synthesis, increases diet-induced thermogenesis (DIT: 20–30% of protein kcal vs 5–10% for carbs/fats), and enhances satiety via GLP-1 and PYY secretion.
A8: 3. MACRONUTRIENT DISTRIBUTION: The 1500 kcal target is distributed as 24% protein (90g), 35% carbohydrate (130g), and 30% fat (50g), with 8% fibre (30g). This moderate-carbohydrate approach supports thyroid function, training performance, and cognitive clarity while maintaining sufficient fat for steroid hormone synthesis and fat-soluble vitamin absorption.
A10: 4. MEAL PATTERNING: Three main meals plus 1–2 snacks distributed across a 10–12 hour eating window (e.g., 08:00–20:00) supports circadian alignment. Front-loading calories (larger breakfast/lunch, moderate dinner) improves glucose tolerance and reduces evening hyperphagia.
A12: 5. FOOD QUALITY HIERARCHY: The programme prioritises whole, minimally processed foods. The NOVA classification system guides selections: Group 1 (unprocessed/minimally processed) forms 80–90% of intake; Group 2 (culinary ingredients) 5–10%; Group 3 (processed foods) ≤10%; Group 4 (ultra-processed) ≤5% (weekly treat meal).
A14: 6. BEHAVIOURAL ADHERENCE MECHANISMS: (a) Flexible eating: one weekly meal ≤800 kcal prevents psychological restriction and supports social participation. (b) Meal prep: batch cooking on Sundays reduces decision fatigue and improves adherence by 40–60%. (c) Self-monitoring: daily food logging increases weight loss success by 2–3x versus non-logging (Burke et al., 2011). (d) Progress photos: visual feedback maintains motivation when scale weight plateaus.
A16: 7. HYDRATION & MICRONUTRIENTS: Water intake of 2.5L/day supports cellular metabolism, thermoregulation, and appetite regulation. The programme emphasises food-first micronutrient acquisition through 5+ vegetable servings and 2+ fruit servings daily. Supplements address only documented gaps (Vitamin D in equatorial latitudes with high indoor exposure; Omega-3 if salmon intake <2x/week).
A18: 8. SLEEP & STRESS INTEGRATION: Sleep restriction to <7 hours increases ghrelin (+28%) and reduces leptin (-18%), amplifying hedonic food cravings (Spiegel et al., 2004). Chronic cortisol elevation promotes visceral adiposity. The programme recommends 7–9 hours sleep and stress-reduction practices (walking, journaling, prayer/meditation) as non-negotiable adjuncts to nutrition.
A20: REFERENCES & EVIDENCE BASE
A21: 1. Arshad, F., et al. (2022). Meal preparation and dietary adherence in Malaysian adults: A cross-sectional study. Journal of Nutrition and Metabolism, 2022, 8845123.
... A47: For personalised medical nutrition therapy in Malaysia, contact: Malaysian Dietitians' Association (MDA) or seek referral from a private hospital dietitian.
